#VRML_SIM R2023b utf8

EXTERNPROTO "https://raw.githubusercontent.com/cyberbotics/webots/R2023b/projects/objects/floors/protos/Floor.proto"
EXTERNPROTO "https://raw.githubusercontent.com/cyberbotics/webots/R2023b/projects/objects/trees/protos/Forest.proto"
EXTERNPROTO "https://raw.githubusercontent.com/cyberbotics/webots/R2023b/projects/appearances/protos/OldSteel.proto"
EXTERNPROTO "https://raw.githubusercontent.com/cyberbotics/webots/R2023b/projects/objects/backgrounds/protos/TexturedBackground.proto"
EXTERNPROTO "https://raw.githubusercontent.com/cyberbotics/webots/R2023b/projects/objects/backgrounds/protos/TexturedBackgroundLight.proto"

WorldInfo {
}
Viewpoint {
  orientation -0.27030514252298304 -0.055912586259588844 0.9611497867779996 3.5341124029807163
  position 3.9628500358857455 2.020415428530913 2.2593461293196473
}
TexturedBackground {
}
TexturedBackgroundLight {
}
Robot {
  translation -0.0030492025821013133 -0.1403443813544718 0.06487299152664532
  rotation -0.9996754007139484 -0.017918393984409663 0.01811144291397727 0.16399057864859176
  children [
    DEF base_torso Shape {
      appearance OldSteel {
      }
      geometry Box {
        size 0.8 0.3 0.1
      }
    }
    DEF rightLeg2 HingeJoint {
      jointParameters HingeJointParameters {
        position 0.9815204267565438
        anchor 0 -0.18 0
      }
      device [
        RotationalMotor {
          name "rightLegVertical1"
        }
      ]
      endPoint Solid {
        translation 0 -0.18 0
        rotation -1.2259127157359589e-08 0.009239655149893417 0.9999573134752858 3.1415900001132724
        children [
          DEF hip_joint Shape {
            appearance PBRAppearance {
              metalness 0
            }
            geometry Sphere {
              radius 0.05
            }
          }
          DEF leftLeftHorizintal1 HingeJoint {
            jointParameters HingeJointParameters {
              position 9.112178613687155e-06
              axis 0 0 1
              stopCFM 2
            }
            device [
              RotationalMotor {
                name "leftLegHorizontal1"
              }
            ]
            endPoint Solid {
              translation 0.0077854345628640435 0.1410680709481262 0.1104619999999997
              rotation 0.6715186362695379 0.658802133133833 -0.3391791127428275 2.562715712843353
              children [
                DEF thigh Shape {
                  appearance PBRAppearance {
                    metalness 0
                  }
                  geometry Cylinder {
                    height 0.3
                    radius 0.03
                  }
                }
                Solid {
                  translation -6.82356197588041e-05 -4.93965396133343e-05 -0.16039615067044916
                  rotation 1.6504199957195536e-05 0.9999999974064502 7.010499981817918e-05 -0.28961530717958617
                  children [
                    DEF knee Shape {
                      appearance PBRAppearance {
                        metalness 0
                      }
                      geometry Sphere {
                        radius 0.05
                      }
                    }
                    Solid {
                      translation 0.19485 0 -0.0142444
                      rotation 0 -1 0 1.5
                      children [
                        DEF leg Shape {
                          appearance PBRAppearance {
                            metalness 0
                          }
                          geometry Cylinder {
                            height 0.4
                            radius 0.03
                          }
                        }
                        Solid {
                          translation 0.000577156 0 -0.21211
                          rotation 0 1 0 0.58
                          children [
                            DEF foot Shape {
                              appearance PBRAppearance {
                                metalness 0
                              }
                              geometry Sphere {
                                radius 0.04
                              }
                            }
                          ]
                          boundingObject USE foot
                          physics DEF dog Physics {
                            mass 1
                          }
                        }
                      ]
                      boundingObject USE leg
                      physics USE dog
                    }
                  ]
                  boundingObject USE knee
                  physics USE dog
                }
              ]
              boundingObject USE thigh
              physics DEF dog Physics {
                mass 1
              }
              linearVelocity -2.534520824566319e-06 -1.455004778022211e-06 -1.755870334818585e-07
              angularVelocity 1.5762499979076731e-06 4.973194982407898e-05 0.0001057407352086304
            }
          }
        ]
        name "solid(2)"
        boundingObject USE hip_joint
        physics DEF dog Physics {
          mass 1
        }
        linearVelocity -3.1721333681987874e-05 -1.6409259406291472e-07 -2.954577785203656e-07
        angularVelocity 2.087923064664275e-06 2.5738054365120793e-05 -1.7493658951345248e-05
      }
    }
    DEF rightLeg3 HingeJoint {
      jointParameters HingeJointParameters {
        position 0.9815237643975334
        anchor 0 -0.18 0
      }
      device [
        RotationalMotor {
          name "rightLegVertical1"
        }
      ]
      endPoint Solid {
        translation 0.27973199999999987 -0.1797410001160698 -0.0002694391115727724
        rotation -2.347620127087229e-05 -0.009222260090757082 -0.9999574737796036 3.141589925626556
        children [
          DEF hip_joint Shape {
            appearance PBRAppearance {
              metalness 0
            }
            geometry Sphere {
              radius 0.05
            }
          }
          DEF leftLeftHorizintal1 HingeJoint {
            jointParameters HingeJointParameters {
              position 7.270505402833718e-06
              axis 0 0 1
              stopCFM 2
            }
            device [
              RotationalMotor {
                name "leftLegHorizontal1"
              }
            ]
            endPoint Solid {
              translation 0.00778569436413801 0.14106805660966068 0.11046199999999945
              rotation 0.6715191804591334 0.6588014534982716 -0.33917935542137423 2.5627163375006603
              children [
                DEF thigh Shape {
                  appearance PBRAppearance {
                    metalness 0
                  }
                  geometry Cylinder {
                    height 0.3
                    radius 0.03
                  }
                }
                Solid {
                  translation -6.82356197588041e-05 -4.93965396133343e-05 -0.16039615067044916
                  rotation 1.6504199957195536e-05 0.9999999974064502 7.010499981817918e-05 -0.28961530717958617
                  children [
                    DEF knee Shape {
                      appearance PBRAppearance {
                        metalness 0
                      }
                      geometry Sphere {
                        radius 0.05
                      }
                    }
                    Solid {
                      translation 0.19485 0 -0.0142444
                      rotation 0 -1 0 1.5
                      children [
                        DEF leg Shape {
                          appearance PBRAppearance {
                            metalness 0
                          }
                          geometry Cylinder {
                            height 0.4
                            radius 0.03
                          }
                        }
                        Solid {
                          translation 0.000577156 0 -0.21211
                          rotation 0 1 0 0.58
                          children [
                            DEF foot Shape {
                              appearance PBRAppearance {
                                metalness 0
                              }
                              geometry Sphere {
                                radius 0.04
                              }
                            }
                          ]
                          boundingObject USE foot
                          physics DEF dog Physics {
                            mass 1
                          }
                        }
                      ]
                      boundingObject USE leg
                      physics USE dog
                    }
                  ]
                  boundingObject USE knee
                  physics USE dog
                }
              ]
              boundingObject USE thigh
              physics DEF dog Physics {
                mass 1
              }
              linearVelocity -2.8415351149462806e-06 -2.6577855508689005e-06 -7.343738154190765e-06
              angularVelocity 1.9938833023119087e-06 4.562042049934902e-05 8.907747740832575e-05
            }
          }
        ]
        name "solid(1)"
        boundingObject USE hip_joint
        physics DEF dog Physics {
          mass 1
        }
        linearVelocity -2.9252421726290378e-05 -3.060341183166004e-06 -7.356351794328467e-06
        angularVelocity 2.288678246031838e-06 2.5474238622536112e-05 -1.5915403261512757e-05
      }
    }
    DEF rightLeg1 HingeJoint {
      jointParameters HingeJointParameters {
        position 0.9815169442943217
        anchor 0 -0.18 0
      }
      device [
        RotationalMotor {
          name "rightLegVertical1"
        }
      ]
      endPoint Solid {
        translation -0.229744 -0.18000000324411805 -0.00012733499995867467
        rotation 3.242048674049154e-05 -0.009260621165089536 -0.9999571190028844 3.1414855043373935
        children [
          DEF hip_joint Shape {
            appearance PBRAppearance {
              metalness 0
            }
            geometry Sphere {
              radius 0.05
            }
          }
          DEF leftLeftHorizintal1 HingeJoint {
            jointParameters HingeJointParameters {
              position 1.5200063480871384e-05
              axis 0 0 1
              stopCFM 2
            }
            device [
              RotationalMotor {
                name "leftLegHorizontal1"
              }
            ]
            endPoint Solid {
              translation 0.007784575756545404 0.14106811834234123 0.11046199999999959
              rotation 0.6715168373770417 0.6588043797526292 -0.33917831053575576 2.562713647962407
              children [
                DEF thigh Shape {
                  appearance PBRAppearance {
                    metalness 0
                  }
                  geometry Cylinder {
                    height 0.3
                    radius 0.03
                  }
                }
                Solid {
                  translation -6.82356197588041e-05 -4.93965396133343e-05 -0.16039615067044916
                  rotation 1.6504199957195536e-05 0.9999999974064502 7.010499981817918e-05 -0.28961530717958617
                  children [
                    DEF knee Shape {
                      appearance PBRAppearance {
                        metalness 0
                      }
                      geometry Sphere {
                        radius 0.05
                      }
                    }
                    Solid {
                      translation 0.19485 0 -0.0142444
                      rotation 0 -1 0 1.5
                      children [
                        DEF leg Shape {
                          appearance PBRAppearance {
                            metalness 0
                          }
                          geometry Cylinder {
                            height 0.4
                            radius 0.03
                          }
                        }
                        Solid {
                          translation 0.000577156 0 -0.21211
                          rotation 0 1 0 0.58
                          children [
                            DEF foot Shape {
                              appearance PBRAppearance {
                                metalness 0
                              }
                              geometry Sphere {
                                radius 0.04
                              }
                            }
                          ]
                          boundingObject USE foot
                          physics DEF dog Physics {
                            mass 1
                          }
                        }
                      ]
                      boundingObject USE leg
                      physics USE dog
                    }
                  ]
                  boundingObject USE knee
                  physics USE dog
                }
              ]
              boundingObject USE thigh
              physics DEF dog Physics {
                mass 1
              }
              linearVelocity -2.224990042059283e-06 -3.4867697039074884e-07 5.98269972113029e-06
              angularVelocity 1.1872861930382535e-06 5.67819362086347e-05 0.00013498153507673303
            }
          }
        ]
        name "solid(3)"
        boundingObject USE hip_joint
        physics DEF dog Physics {
          mass 1
        }
        linearVelocity -3.615147086649369e-05 2.732139067984389e-06 5.697865063666537e-06
        angularVelocity 1.977571514544307e-06 2.620686937748735e-05 -1.9204829509233967e-05
      }
    }
    DEF leftLeg1 HingeJoint {
      jointParameters HingeJointParameters {
        position 1.4678824445590168
        anchor 0 0.18 0
      }
      device [
        RotationalMotor {
          name "rightLegVertical1"
        }
      ]
      endPoint Solid {
        translation 0.2900039999999999 0.1799641646135521 0.0003291508735247716
        rotation 0.9999999974578377 -7.129960292990622e-05 8.313483763916791e-07 0.467882905659152
        children [
          DEF hip_joint Shape {
            appearance PBRAppearance {
              metalness 0
            }
            geometry Sphere {
              radius 0.05
            }
          }
          DEF leftLeftHorizintal1 HingeJoint {
            jointParameters HingeJointParameters {
              position -4.643210571390893e-06
              axis 0 0 1
              stopCFM 2
            }
            device [
              RotationalMotor {
                name "leftLegHorizontal1"
              }
            ]
            endPoint Solid {
              translation 0.007787375008344898 0.14106796384309772 0.11046199999999938
              rotation 0.6715227007858267 0.6587970569509819 -0.3391809252921426 2.5627203783965182
              children [
                DEF thigh Shape {
                  appearance PBRAppearance {
                    metalness 0
                  }
                  geometry Cylinder {
                    height 0.3
                    radius 0.03
                  }
                }
                Solid {
                  translation -6.82356197588041e-05 -4.93965396133343e-05 -0.16039615067044916
                  rotation 1.6504199957195536e-05 0.9999999974064502 7.010499981817918e-05 -0.28961530717958617
                  children [
                    DEF knee Shape {
                      appearance PBRAppearance {
                        metalness 0
                      }
                      geometry Sphere {
                        radius 0.05
                      }
                    }
                    Solid {
                      translation 0.19485 0 -0.0142444
                      rotation 0 -1 0 1.5
                      children [
                        DEF leg Shape {
                          appearance PBRAppearance {
                            metalness 0
                          }
                          geometry Cylinder {
                            height 0.4
                            radius 0.03
                          }
                        }
                        Solid {
                          translation 0.000577156 0 -0.21211
                          rotation 0 1 0 0.58
                          children [
                            DEF foot Shape {
                              appearance PBRAppearance {
                                metalness 0
                              }
                              geometry Sphere {
                                radius 0.04
                              }
                            }
                          ]
                          boundingObject USE foot
                          physics DEF dog Physics {
                            mass 1
                          }
                        }
                      ]
                      boundingObject USE leg
                      physics USE dog
                    }
                  ]
                  boundingObject USE knee
                  physics USE dog
                }
              ]
              boundingObject USE thigh
              physics DEF dog Physics {
                mass 1
              }
              linearVelocity 6.368441417946126e-06 -7.981369880251276e-07 -6.651846989825594e-06
              angularVelocity 1.1383795795642194e-06 7.492308892934571e-05 -0.00014728523405364635
            }
          }
        ]
        name "solid(5)"
        boundingObject USE hip_joint
        physics DEF dog Physics {
          mass 1
        }
        linearVelocity -2.067068680957675e-05 8.014586975241236e-08 -6.331269730821994e-06
        angularVelocity 6.697059286072543e-07 2.495951395498077e-05 -3.108210943958407e-06
      }
    }
    DEF leftLeg2 HingeJoint {
      jointParameters HingeJointParameters {
        position 1.4760762138499577
        anchor 0 0.18 0
      }
      device [
        RotationalMotor {
          name "rightLegVertical1"
        }
      ]
      endPoint Solid {
        translation 0.04000000000000002 0.17999300001719615 4.049490297254303e-05
        rotation 0.9999999999355013 3.147383318554174e-06 -1.0912906940882272e-05 0.47607602860823156
        children [
          DEF hip_joint Shape {
            appearance PBRAppearance {
              metalness 0
            }
            geometry Sphere {
              radius 0.05
            }
          }
          DEF leftLeftHorizintal1 HingeJoint {
            jointParameters HingeJointParameters {
              position 4.0164832442226015e-05
              axis 0 0 1
              stopCFM 2
            }
            device [
              RotationalMotor {
                name "leftLegHorizontal1"
              }
            ]
            endPoint Solid {
              translation 0.007781054021137698 0.1410683126385168 0.1104619999999995
              rotation 0.6715094605312841 0.6588135924815052 -0.33917502086474005 2.5627051804953114
              children [
                DEF thigh Shape {
                  appearance PBRAppearance {
                    metalness 0
                  }
                  geometry Cylinder {
                    height 0.3
                    radius 0.03
                  }
                }
                Solid {
                  translation -6.82356197588041e-05 -4.93965396133343e-05 -0.16039615067044916
                  rotation 1.6504199957195536e-05 0.9999999974064502 7.010499981817918e-05 -0.28961530717958617
                  children [
                    DEF knee Shape {
                      appearance PBRAppearance {
                        metalness 0
                      }
                      geometry Sphere {
                        radius 0.05
                      }
                    }
                    Solid {
                      translation 0.19485 0 -0.0142444
                      rotation 0 -1 0 1.5
                      children [
                        DEF leg Shape {
                          appearance PBRAppearance {
                            metalness 0
                          }
                          geometry Cylinder {
                            height 0.4
                            radius 0.03
                          }
                        }
                        Solid {
                          translation 0.000577156 0 -0.21211
                          rotation 0 1 0 0.58
                          children [
                            DEF foot Shape {
                              appearance PBRAppearance {
                                metalness 0
                              }
                              geometry Sphere {
                                radius 0.04
                              }
                            }
                          ]
                          boundingObject USE foot
                          physics DEF dog Physics {
                            mass 1
                          }
                        }
                      ]
                      boundingObject USE leg
                      physics USE dog
                    }
                  ]
                  boundingObject USE knee
                  physics USE dog
                }
              ]
              boundingObject USE thigh
              physics DEF dog Physics {
                mass 1
              }
              linearVelocity 1.2210975966883424e-06 -5.021372117113044e-07 -2.8414972570090306e-07
              angularVelocity 2.1620857079408054e-06 3.2897824022089916e-05 -3.756008340684747e-05
            }
          }
        ]
        name "solid(4)"
        boundingObject USE hip_joint
        physics DEF dog Physics {
          mass 1
        }
        linearVelocity -1.0910966778178904e-05 -1.003388382151175e-07 -3.678041624084454e-07
        angularVelocity 2.0864453584598424e-06 2.44914467284318e-05 -1.3208121857427607e-05
      }
    }
    DEF leftLeg3 HingeJoint {
      jointParameters HingeJointParameters {
        position 1.4760852039628358
        anchor 0 0.18 0
      }
      device [
        RotationalMotor {
          name "rightLegVertical1"
        }
      ]
      endPoint Solid {
        translation -0.20999999999999983 0.17999199932686982 7.815033109094215e-05
        rotation 0.9999999996572988 2.1177960353098888e-05 -1.5391440338407876e-05 0.47608276162855634
        children [
          DEF hip_joint Shape {
            appearance PBRAppearance {
              metalness 0
            }
            geometry Sphere {
              radius 0.05
            }
          }
          DEF leftLeftHorizintal1 HingeJoint {
            jointParameters HingeJointParameters {
              position 3.7293338907041255e-05
              axis 0 0 1
              stopCFM 2
            }
            device [
              RotationalMotor {
                name "leftLegHorizontal1"
              }
            ]
            endPoint Solid {
              translation 0.007781459097853381 0.1410682902946889 0.11046199999999949
              rotation 0.6715103090356963 0.6588125328203764 -0.3391753992517501 2.5627061544347343
              children [
                DEF thigh Shape {
                  appearance PBRAppearance {
                    metalness 0
                  }
                  geometry Cylinder {
                    height 0.3
                    radius 0.03
                  }
                }
                Solid {
                  translation -6.82356197588041e-05 -4.93965396133343e-05 -0.16039615067044916
                  rotation 1.6504199957195536e-05 0.9999999974064502 7.010499981817918e-05 -0.28961530717958617
                  children [
                    DEF knee Shape {
                      appearance PBRAppearance {
                        metalness 0
                      }
                      geometry Sphere {
                        radius 0.05
                      }
                    }
                    Solid {
                      translation 0.19485 0 -0.0142444
                      rotation 0 -1 0 1.5
                      children [
                        DEF leg Shape {
                          appearance PBRAppearance {
                            metalness 0
                          }
                          geometry Cylinder {
                            height 0.4
                            radius 0.03
                          }
                        }
                        Solid {
                          translation 0.000577156 0 -0.21211
                          rotation 0 1 0 0.58
                          children [
                            DEF foot Shape {
                              appearance PBRAppearance {
                                metalness 0
                              }
                              geometry Sphere {
                                radius 0.04
                              }
                            }
                          ]
                          boundingObject USE foot
                          physics DEF dog Physics {
                            mass 1
                          }
                        }
                      ]
                      boundingObject USE leg
                      physics USE dog
                    }
                  ]
                  boundingObject USE knee
                  physics USE dog
                }
              ]
              boundingObject USE thigh
              physics DEF dog Physics {
                mass 1
              }
              linearVelocity 2.231209153239323e-06 1.6739871206133724e-06 3.117181619018079e-06
              angularVelocity -7.668231952732719e-06 4.213667682117255e-05 -6.0883120653366685e-05
            }
          }
        ]
        name "solid(6)"
        boundingObject USE hip_joint
        physics DEF dog Physics {
          mass 1
        }
        linearVelocity -1.3071740128803186e-05 1.3139812828928402e-06 5.778667766264787e-06
        angularVelocity -7.78143022649431e-06 2.457418566025047e-05 -1.0948671411270554e-05
      }
    }
  ]
  boundingObject USE base_torso
  physics DEF dog Physics {
    mass 1
  }
  controller ""
}
Forest {
  density 0.08
}
Floor {
  translation 0 0 -0.01
}
